Workbook

Sheet Cover
B2: PFIZER – METSERA M&A VALUATION MODEL
B3: CVR Binomial Tree Pricing | GLP-1 Acquisition Analysis
B4: Course: Financial Instruments & Risk Management | 2025–2026 Spring
B7: DEAL SNAPSHOT
B8: Acquirer | E8: Pfizer Inc (PFE.US)
B9: Target | E9: Metsera, Inc.
B10: Deal Close | E10: November 13, 2025
B11: Cash Consideration | E11: $65.60 / share (~$7.0bn enterprise value)
B12: CVR (max) | E12: $20.65 / share (up to ~$2.3bn)
B13: CVR Fair Value (10-Q) | E13: $632 million (Pfizer FY2026 Q1 10-Q)
B14: Total Fair Value | E14: $8.0 billion (incl. CVR & employee awards)
B15: Milestone 1 | E15: $4.60/sh → Phase 3 start: MET-097i + MET-233i combo
B16: Milestone 2 | E16: $6.40/sh → FDA approval: monthly MET-097i monotherapy
B17: Milestone 3 | E17: $9.65/sh → FDA approval: monthly MET-097i + MET-233i
B20: MODEL NAVIGATION
B21: Assumptions | D21: All model inputs — blue = hard-coded, yellow = key assumption
B22: Pfizer Financials | D22: Abbreviated P&L, Balance Sheet, and Cash Flow (2023–2030E)
B23: Metsera rNPV | D23: Risk-adjusted NPV of MET-097i drug program (underlying S₀)
B24: CVR Binomial Tree | D24: 3-step binomial tree — CVR fair value via backward induction
B25: Deal Valuation | D25: Full M&A consideration waterfall and implied deal metrics
B26: Sensitivity | D26: CVR fair value vs. milestone probability and discount rate
B29: COLOUR CONVENTION
B30: Blue text | D30: Hard-coded inputs (change for scenarios)
B31: Black text | D31: Formulas and calculated values
B32: Green text | D32: Cross-sheet links
B33: Yellow fill | D33: Key assumptions requiring attention
B36: Sources: Pfizer 10-Q Q1 2026 (SEC EDGAR); CICC Research Financial Model (2024); Metsera VESPER-1 Phase 2b Press Release (Sep 2025); IQVIA Obesity Market Revolution (Jul 2025)

Sheet Assumptions
B1: MODEL ASSUMPTIONS
B3: A. DEAL STRUCTURE (Source: Pfizer 10-Q Q1 2026, SEC EDGAR)
B4: Cash price per share ($) | C4: 65.6 | D4: Source: Pfizer 10-Q Q1 2026
B5: Shares outstanding (millions) | C5: 111.4 | D5: Calc: $2.3bn / $20.65 CVR max
B6: Cash enterprise value ($mn) | C6: =C4*C5 -> 7307.84 | D6: =C4 * C5 -> 7307.84
B7: CVR max per share ($) | C7: 20.65 | D7: Source: Pfizer 10-Q Q1 2026
B8: CVR nominal total ($mn) | C8: 2300 | D8: Source: Pfizer 10-Q Q1 2026
B9: CVR Milestone 1 per share ($) | C9: 4.6 | D9: Phase 3 start: MET-097i+MET-233i combo
B10: CVR Milestone 2 per share ($) | C10: 6.4 | D10: FDA approval: MET-097i monotherapy
B11: CVR Milestone 3 per share ($) | C11: 9.65 | D11: FDA approval: MET-097i+MET-233i combo
B12: M1 total payment ($mn) | C12: =C9*C5 -> 512.44 | D12: =@M1 per share *@ shares
B13: M2 total payment ($mn) | C13: =C10*C5 -> 712.96 | D13: =@M2 per share *@ shares
B14: M3 total payment ($mn) | C14: =C11*C5 -> 1075.01 | D14: =@M3 per share *@ shares
B15: CVR fair value per Pfizer ($mn) | C15: 632 | D15: Source: Pfizer 10-Q Q1 2026, Note 2A
B16: Employee stock awards ($mn) | C16: 475 | D16: Source: Pfizer 10-Q Q1 2026, Note 2A
B17: Total fair value of deal ($mn) | C17: =C6+C15+C16 -> 8414.84 | D17: Cash + CVR FV + Awards
B19: B. BINOMIAL TREE PARAMETERS (CVR Valuation Inputs)
B20: Risk-free rate (r) | C20: 0.045 | D20: US 10Y Treasury yield, May 2026
B21: Drug program volatility (σ) | C21: 0.55 | D21: Clinical-stage pharma vol (high)
B22: Drug program current value S₀ ($mn) | C22: ='Metsera rNPV'!C32 -> 2573.6046 | D22: Estimated rNPV — see Metsera rNPV sheet
B23: Time to Milestone 1 (T₁, years) | C23: 0.5 | D23: Phase 3 start: ~6 months post-close
B24: Time to Milestone 2 (T₂, years) | C24: 3 | D24: FDA approval mono: ~2028
B25: Time to Milestone 3 (T₃, years) | C25: 4 | D25: FDA approval combo: ~2029
B26: Step 1 length Δt₁ (years) | C26: =C23 -> 0.5 | D26: @T₁
B27: Step 2 length Δt₂ (years) | C27: =C24-C23 -> 2.5
B28: Step 3 length Δt₃ (years) | C28: =C25-C24 -> 1
B29: Up factor Step 1 (u₁) | C29: =EXP(C21*SQRT(C26)) -> 1.4753699 | D29: @e^(@σ√Δt₁)
B30: Down factor Step 1 (d₁) | C30: =1/C29 -> 0.67779613 | D30: =1/@u₁
B31: Risk-neutral prob Step 1 (p₁) | C31: =( EXP(C20*C26)-C30)/(C29-C30) -> 0.43251035 | D31: =(@e^@rΔt₁-@d₁)/(@u₁-@d₁)
B32: Up factor Step 2 (u₂) | C32: =EXP(C21*SQRT(C27)) -> 2.3860192 | D32: =@e^(@σ√Δt₂)
B33: Down factor Step 2 (d₂) | C33: =1/C32 -> 0.41910812 | D33: =1/@u₂
B34: Risk-neutral prob Step 2 (p₂) | C34: =(EXP(C20*C27)-C33)/(C32-C33) -> 0.35586975 | D34: =(@e^@rΔt₂-@d₂)/(@u₂-@d₂)
B35: Up factor Step 3 (u₃) | C35: =EXP(C21*SQRT(C28)) -> 1.733253 | D35: =@e^(@σ√Δt₃)
B36: Down factor Step 3 (d₃) | C36: =1/C35 -> 0.57694981 | D36: =1/@u₃
B37: Risk-neutral prob Step 3 (p₃) | C37: =(EXP(C20*C28)-C36)/(C35-C36) -> 0.40567046 | D37: =(@e^@rΔt₃-@d₃)/(@u₃-@d₃)
B39: C. MILESTONE SUCCESS PROBABILITIES (Real-world; for calibration / scenario)
B40: P(M1): Phase 3 start probability | C40: 0.85 | D40: Operational milestone; management decision
B41: P(M2): FDA approval – monotherapy | C41: 0.62 | D41: GLP-1 Phase 3→approval historical rate ~60–70%
B42: P(M3|M2): Combo approval given mono | C42: 0.55 | D42: Additional regulatory hurdle for combo
B43: P(M3): Combined combo prob [M2×M3|M2] | C43: =C41*C42 -> 0.341
...

Sheet Pfizer Financials
B1: PFIZER INC (PFE.US) — FINANCIAL SUMMARY
B2: Source: CICC Research Financial Model (Yuan GAO, 2024). Units: USD millions. A = Actual; E = Estimate. Data per RAWS sheet of uploaded model.
B4: ($mn) | C4: 2023 (A) | D4: 2024 (A) | E4: 2025 (A) | F4: 2026 (E) | G4: 2027 (E) | H4: 2028 (E) | I4: 2029 (E) | J4: 2030 (E)
B5: INCOME STATEMENT
B6: Net Revenue | C6: 59553 | D6: 63627 | E6: 62579 | F6: 61331 | G6: 58676 | H6: 55677 | I6: 55162 | J6: 56282
B7: Gross Profit | C7: 34599 | D7: 45776 | E7: 46512 | F7: 45584 | G7: 43611 | H7: 41382 | I7: 40889 | J7: 41607
B8: Gross Margin | C8: 0.58097829 | D8: 0.719443 | E8: 0.74325253 | F8: 0.74324567 | G8: 0.74325107 | H8: 0.74325125 | I8: 0.74125304 | J8: 0.73925944
B9: EBITDA | C9: 7932 | D9: 17582 | E9: 16181 | F9: 15092 | G9: 14583 | H9: 13817 | I9: 13811 | J9: 14487
B10: EBITDA Margin | C10: 0.13319228 | D10: 0.27632923 | E10: 0.25856917 | F10: 0.24607458 | G10: 0.24853432 | H10: 0.24816351 | I10: 0.25037163 | J10: 0.25740023
B11: EBIT | C11: 1642 | D11: 10569 | E11: 9589 | F11: 8945 | G11: 8365 | H11: 7530 | I11: 7450 | J11: 8044
B12: Net Profit (GAAP) | C12: 2118 | D12: 8031 | E12: 7771 | F12: 6199 | G12: 5722 | H12: 5010 | I12: 4908 | J12: 5394
B13: Net Margin | C13: 0.035564959 | D13: 0.12622 | E13: 0.12417904 | F13: 0.1010745 | G13: 0.097518577 | H13: 0.089983297 | I13: 0.088974294 | J13: 0.095838812
B14: Recurrent Net Profit | C14: 10501 | D14: 17716 | E14: 18406 | F14: 16709 | G14: 16138 | H14: 14442 | I14: 13673 | J14: 14015
B15: R&D Expenses | C15: 10679 | D15: 10822 | E15: 10437 | F15: 10549 | G15: 9975 | H15: 9465 | I15: 9378 | J15: 9512
B17: BALANCE SHEET HIGHLIGHTS
B18: Total Assets | C18: 226501 | D18: 213396 | E18: 208160 | F18: 204469 | G18: 200133 | H18: 195341 | I18: 193228 | J18: 191221
B19: Total Equity | C19: 89014 | D19: 88203 | E19: 86476 | F19: 83188 | G19: 79281 | H19: 74775 | I19: 70168 | J19: 66047
B20: Long-Term Debt | C20: 61358 | D20: 57405 | E20: 61641 | F20: 61641 | G20: 61641 | H20: 61641 | I20: 63641 | J20: 65641
B21: Net Debt | C21: 58505 | D21: 56362 | E21: 60498 | F21: 60173 | G21: 60027 | H21: 60113 | I21: 60408 | J21: 61082
B23: CASH FLOW HIGHLIGHTS
B24: Operating Cash Flow | C24: 8700 | D24: 12744 | E24: 11704 | F24: 12111 | G24: 11775 | H24: 11083 | I24: 10920 | J24: 11282
B25: Capital Expenditure | C25: -3907 | D25: -2909 | E25: -2629 | F25: -2000 | G25: -2000 | H25: -2000 | I25: -2200 | J25: -2440
B26: Free Cash Flow | C26: 2383 | D26: 9089 | E26: 6396 | F26: 10152 | G26: 9816 | H26: 9124 | I26: 8761 | J26: 8883
B27: Dividends Paid | C27: -9248 | D27: -9512 | E27: -9771 | F27: -9826 | G27: -9670 | H27: -9556 | I27: -9556 | J27: -9556
B29: ⚠ Patent Cliff Note: Pfizer faces ~$17–20bn revenue loss from patent expirations over 2025–2030E (analyst consensus, UBS/Bloomberg). The Metsera acquisition targets replacement of this revenue via GLP-1/obesity assets by 2030.

Sheet Metsera rNPV
B1: METSERA MET-097i — RISK-ADJUSTED NPV (rNPV)
B2: Purpose: Derives S₀ = current value of MET-097i drug program, used as the underlying asset in the CVR Binomial Tree. rNPV = Σ [Peak Sales × Margin × P(success) × Discount].
B4: A. MARKET SIZING ASSUMPTIONS
B5: Global obesity drug market 2024 ($bn) | C5: 30 | D5: IQVIA Obesity Market Revolution, Jul 2025
B6: Market CAGR 2024–2030 (%) | C6: 0.22 | D6: Analyst consensus; GLP-1 volume growth
B7: Estimated market size 2030 ($bn) | C7: =C5*(1+C6)^6 -> 98.919119
B8: MET-097i peak market share (%) | C8: 0.06 | D8: Conservative: ~6% in competitive market
B9: MET-097i peak sales ($bn) | C9: =C7*C8 -> 5.9351471
B10: Net margin on peak sales (%) | C10: 0.35 | D10: Pharma average operating margin
B11: Peak year net income ($bn) | C11: =C9*C10 -> 2.0773015 | D11: =@Peak sales *@ margin
B12: P/E multiple applied | C12: 22 | D12: Pharma sector P/E (consensus ~20–25x)
B13: Undiscounted terminal value ($bn) | C13: =C11*C12 -> 45.700633 | D13: =@Net income *@ P/@e
B15: B. PROBABILITY OF SUCCESS BY STAGE
B16: Stage | C16: Stage Success Rate | D16: Cumulative P(success) | E16: Note
B17: Preclinical → Phase 1 | C17: 0.63 | D17: =C17 -> 0.63 | E17: Historical oncology/metabolic
B18: Phase 1 → Phase 2 | C18: 0.52 | D18: =C17*C18 -> 0.3276 | E18: Industry average
B19: Phase 2 → Phase 3 | C19: 0.58 | D19: =D18*C19 -> 0.190008 | E19: Metabolic disease slightly above avg
B20: Phase 3 → FDA Approval | C20: 0.65 | D20: =D19*C20 -> 0.1235052 | E20: GLP-1 historical ~60–70%
B21: FDA Approval → Launch | C21: 0.9 | D21: =D20*C21 -> 0.11115468 | E21: Regulatory/manufacturing risk
B23: C. rNPV CALCULATION — CURRENT STAGE: PHASE 2b COMPLETE
B24: Current stage | C24: Phase 2b complete (VESPER-1 results Sep 2025)
B25: Cumulative P(success) from Phase 3 | C25: =D20*C21 -> 0.11115468
B26: Discount rate for pharma asset (%) | C26: 0.12 | D26: WACC for clinical-stage pharma: 12%
B27: Years to peak sales | C27: 6 | D27: ~2031 peak (approved ~2029, ramp 2 yr)
B28: Discount factor | C28: =1/(1+C26)^C27 -> 0.50663112
B29: Undiscounted terminal value ($bn) | C29: =C13 -> 45.700633 | D29: ← from Section A
B30: Probability-adjusted terminal value ($bn) | C30: =C29*C25 -> 5.0798392
B31: Risk-adjusted NPV ($bn) [S₀] | C31: =C30*C28 -> 2.5736046 | D31: =@rNPV *@ discount factor
B32: S₀ in $millions (→ Binomial Tree) | C32: =C31*1000 -> 2573.6046 | D32: × 1000 to convert bn → mn

Sheet CVR Binomial Tree
B1: CVR VALUATION — 3-STEP BINOMIAL TREE (Hull Ch.12 Framework)
B2: Method: Non-recombining binomial tree with 3 steps matching each CVR milestone. Underlying S = drug program value (rNPV). Up/down factors from σ. Risk-neutral probabilities p = (e^rΔt − d)/(u − d). CVR = sum of binary payoffs discounted back to t=0.
B4: PARAMETERS (linked from Assumptions sheet)
B5: S₀ Drug program value ($mn) | C5: =Assumptions!C22 -> 2573.6046 | K5: M1 payment ($mn) | L5: =Assumptions!C12 -> 512.44
B6: σ Volatility | C6: =Assumptions!C21 -> 0.55 | K6: M2 payment ($mn) | L6: =Assumptions!C13 -> 712.96
B7: r Risk-free rate | C7: =Assumptions!C20 -> 0.045 | K7: M3 payment ($mn) | L7: =Assumptions!C14 -> 1075.01
B8: Δt₁ Step 1 length (yr) | C8: =Assumptions!C26 -> 0.5 | K8: T₁ years to M1 | L8: =Assumptions!C23 -> 0.5
B9: Δt₂ Step 2 length (yr) | C9: =Assumptions!C27 -> 2.5 | K9: T₂ years to M2 | L9: =Assumptions!C24 -> 3
B10: Δt₃ Step 3 length (yr) | C10: =Assumptions!C28 -> 1 | K10: T₃ years to M3 | L10: =Assumptions!C25 -> 4
B11: u₁ / d₁ / p₁ | C11: =Assumptions!C29&" / "&TEXT(Assumptions!C30,"0.0000")&" / "&TEXT(Assumptions!C31,"0.0000") -> 1.47536988766556 / 0.6778 / 0.4325 | K11: u₂ / d₂ / p₂ | L11: =TEXT(Assumptions!C32,"0.0000")&" / "&TEXT(Assumptions!C33,"0.0000")&" / "&TEXT(Assumptions!C34,"0.0000") -> 2.3860 / 0.4191 / 0.3559
B12: u₃ / d₃ / p₃ | C12: =TEXT(Assumptions!C35,"0.0000")&" / "&TEXT(Assumptions!C36,"0.0000")&" / "&TEXT(Assumptions!C37,"0.0000") -> 1.7333 / 0.5769 / 0.4057
B14: STEP 1 — DRUG PROGRAM VALUE TREE (S = rNPV, $mn)
C15: t=0 (Nov 2025) | E15: t=T₁ (M1) | G15: t=T₂ (M2) | I15: t=T₃ (M3)
H16: ↗ | I16: =G17*Assumptions!C35 -> 15702.856
F17: ↗ | G17: =E19*Assumptions!C32 -> 9059.7596 | H17: [Suu]
H18: ↘ | I18: =G17*Assumptions!C36 -> 5227.0266
D19: ↗ | E19: =C23*Assumptions!C29 -> 3797.0188 | F19: [Su]
H20: ↗ | I20: =G21*Assumptions!C35 -> 2758.2319
F21: ↘ | G21: =E19*Assumptions!C33 -> 1591.3614 | H21: [Sud]
H22: ↘ | I22: =G21*Assumptions!C36 -> 918.13566
C23: =Assumptions!C22 -> 2573.6046
H24: ↗ | I24: =G25*Assumptions!C35 -> 7214.0111
F25: ↗ | G25: =E27*Assumptions!C32 -> 4162.1224 | H25: [Sdu]
H26: ↘ | I26: =G25*Assumptions!C36 -> 2401.3357
D27: ↘ | E27: =C23*Assumptions!C30 -> 1744.3793 | F27: [Sd]
H28: ↗ | I28: =G29*Assumptions!C35 -> 1267.1527
F29: ↘ | G29: =E27*Assumptions!C33 -> 731.08351 | H29: [Sdd]
H30: ↘ | I30: =G29*Assumptions!C36 -> 421.79849
B33: STEP 2 — CVR PAYOFF AT EACH TERMINAL NODE ($mn)
B34: Terminal Node | C34: Path | D34: S(T₁) | E34: M1 Pay? | F34: S(T₂) | G34: M2 Pay? | H34: S(T₃) | I34: M3 Pay? | J34: Total CVR Payoff ($mn) | K34: Path Prob | L34: PV of Payoff
B35: UUU | C35: Up-Up-Up | D35: =E19 -> 3797.0188 | E35: =IF(E19>Assumptions!C46,"YES","NO") -> YES | F35: =G17 -> 9059.7596 | G35: =IF(G17>Assumptions!C47,"YES","NO") -> YES | H35: =I16 -> 15702.856 | I35: =IF(AND(I16>Assumptions!C48,G17>Assumptions!C47),"YES","NO") -> YES | J35: =IF(E19>Assumptions!C46,Assumptions!C12,0)+IF(G17>Assumptions!C47,Assumptions!C13,0)+IF(AND(I16>Assumptions!C48,G17>Assumptions!C47),Assumptions!C14,0) -> 2300.41 | K35: =Assumptions!C31*Assumptions!C34*Assumptions!C37 -> 0.062439721 | L35: =(IF(E19>Assumptions!C46,Assumptions!C12*EXP(-Assumptions!C20*Assumptions!C23),0)+IF(G17>Assumptions!C47,Assumptions!C13*EXP(-Assumptions!C20*Assumptions!C24),0)+IF(AND(I16>Assumptions!C48,G17>Assumptions!C47),Assumptions!C14*EXP(-Assumptions!C20*Assumptions!C25),0))*Assumptions!C31*Assumptions!C34*Assumptions!C37 -> 126.24607
B36: UUD | C36: Up-Up-Down | D36: =E19 -> 3797.0188 | E36: =IF(E19>Assumptions!C46,"YES","NO") -> YES | F36: =G17 -> 9059.7596 | G36: =IF(G17>Assumptions!C47,"YES","NO") -> YES | H36: =I18 -> 5227.0266 | I36: =IF(AND(I18>Assumptions!C48,G17>Assumptions!C47),"YES","NO") -> YES | J36: =IF(E19>Assumptions!C46,Assumptions!C12,0)+IF(G17>Assumptions!C47,Assumptions!C13,0)+IF(AND(I18>Assumptions!C48,G17>Assumptions!C47),Assumptions!C14,0) -> 2300.41 | K36: =Assumptions!C31*Assumptions!C34*(1-Assumptions!C37) -> 0.091477628 | L36: =(IF(E19>Assumptions!C46,Assumptions!C12*EXP(-Assumptions!C20*Assumptions!C23),0)+IF(G17>Assumptions!C47,Assumptions!C13*EXP(-Assumptions!C20*Assumptions!C24),0)+IF(AND(I18>Assumptions!C48,G17>Assumptions!C47),Assumptions!C14*EXP(-Assumptions!C20*Assumptions!C25),0))*Assumptions!C31*Assumptions!C34*(1-Assumptions!C37) -> 184.95744
B37: UDU | C37: Up-Down-Up | D37: =E19 -> 3797.0188 | E37: =IF(E19>Assumptions!C46,"YES","NO") -> YES | F37: =G21 -> 1591.3614 | G37: =IF(G21>Assumptions!C47,"YES","NO") -> NO | H37: =I20 -> 2758.2319 | I37: =IF(AND(I20>Assumptions!C48,G21>Assumptions!C47),"YES","NO") -> NO | J37: =IF(E19>Assumptions!C46,Assumptions!C12,0)+IF(G21>Assumptions!C47,Assumptions!C13,0)+IF(AND(I20>Assumptions!C48,G21>Assumptions!C47),Assumptions!C14,0) -> 512.44 | K37: =Assumptions!C31*(1-Assumptions!C34)*Assumptions!C37 -> 0.11301695 | L37: =(IF(E19>Assumptions!C46,Assumptions!C12*EXP(-Assumptions!C20*Assumptions!C23),0)+IF(G21>Assumptions!C47,Assumptions!C13*EXP(-Assumptions!C20*Assumptions!C24),0)+IF(AND(I20>Assumptions!C48,G21>Assumptions!C47),Assumptions!C14*EXP(-Assumptions!C20*Assumptions!C25),0))*Assumptions!C31*(1-Assumptions!C34)*Assumptions!C37 -> 56.625882
B38: UDD | C38: Up-Down-Down | D38: =E19 -> 3797.0188 | E38: =IF(E19>Assumptions!C46,"YES","NO") -> YES | F38: =G21 -> 1591.3614 | G38: =IF(G21>Assumptions!C47,"YES","NO") -> NO | H38: =I22 -> 918.13566 | I38: =IF(AND(I22>Assumptions!C48,G21>Assumptions!C47),"YES","NO") -> NO | J38: =IF(E19>Assumptions!C46,Assumptions!C12,0)+IF(G21>Assumptions!C47,Assumptions!C13,0)+IF(AND(I22>Assumptions!C48,G21>Assumptions!C47),Assumptions!C14,0) -> 512.44 | K38: =Assumptions!C31*(1-Assumptions!C34)*(1-Assumptions!C37) -> 0.16557605 | L38: =(IF(E19>Assumptions!C46,Assumptions!C12*EXP(-Assumptions!C20*Assumptions!C23),0)+IF(G21>Assumptions!C47,Assumptions!C13*EXP(-Assumptions!C20*Assumptions!C24),0)+IF(AND(I22>Assumptions!C48,G21>Assumptions!C47),Assumptions!C14*EXP(-Assumptions!C20*Assumptions!C25),0))*Assumptions!C31*(1-Assumptions!C34)*(1-Assumptions!C37) -> 82.960033
B39: DUU | C39: Down-Up-Up | D39: =E27 -> 1744.3793 | E39: =IF(E27>Assumptions!C46,"YES","NO") -> YES | F39: =G25 -> 4162.1224 | G39: =IF(G25>Assumptions!C47,"YES","NO") -> YES | H39: =I24 -> 7214.0111 | I39: =IF(AND(I24>Assumptions!C48,G25>Assumptions!C47),"YES","NO") -> YES | J39: =IF(E27>Assumptions!C46,Assumptions!C12,0)+IF(G25>Assumptions!C47,Assumptions!C13,0)+IF(AND(I24>Assumptions!C48,G25>Assumptions!C47),Assumptions!C14,0) -> 2300.41 | K39: =(1-Assumptions!C31)*Assumptions!C34*Assumptions!C37 -> 0.081926122 | L39: =(IF(E27>Assumptions!C46,Assumptions!C12*EXP(-Assumptions!C20*Assumptions!C23),0)+IF(G25>Assumptions!C47,Assumptions!C13*EXP(-Assumptions!C20*Assumptions!C24),0)+IF(AND(I24>Assumptions!C48,G25>Assumptions!C47),Assumptions!C14*EXP(-Assumptions!C20*Assumptions!C25),0))*(1-Assumptions!C31)*Assumptions!C34*Assumptions!C37 -> 165.64537
B40: DUD | C40: Down-Up-Down | D40: =E27 -> 1744.3793 | E40: =IF(E27>Assumptions!C46,"YES","NO") -> YES | F40: =G25 -> 4162.1224 | G40: =IF(G25>Assumptions!C47,"YES","NO") -> YES | H40: =I26 -> 2401.3357 | I40: =IF(AND(I26>Assumptions!C48,G25>Assumptions!C47),"YES","NO") -> YES | J40: =IF(E27>Assumptions!C46,Assumptions!C12,0)+IF(G25>Assumptions!C47,Assumptions!C13,0)+IF(AND(I26>Assumptions!C48,G25>Assumptions!C47),Assumptions!C14,0) -> 2300.41 | K40: =(1-Assumptions!C31)*Assumptions!C34*(1-Assumptions!C37) -> 0.12002628 | L40: =(IF(E27>Assumptions!C46,Assumptions!C12*EXP(-Assumptions!C20*Assumptions!C23),0)+IF(G25>Assumptions!C47,Assumptions!C13*EXP(-Assumptions!C20*Assumptions!C24),0)+IF(AND(I26>Assumptions!C48,G25>Assumptions!C47),Assumptions!C14*EXP(-Assumptions!C20*Assumptions!C25),0))*(1-Assumptions!C31)*Assumptions!C34*(1-Assumptions!C37) -> 242.67959
B41: DDU | C41: Down-Down-Up | D41: =E27 -> 1744.3793 | E41: =IF(E27>Assumptions!C46,"YES","NO") -> YES | F41: =G29 -> 731.08351 | G41: =IF(G29>Assumptions!C47,"YES","NO") -> NO | H41: =I28 -> 1267.1527 | I41: =IF(AND(I28>Assumptions!C48,G29>Assumptions!C47),"YES","NO") -> NO | J41: =IF(E27>Assumptions!C46,Assumptions!C12,0)+IF(G29>Assumptions!C47,Assumptions!C13,0)+IF(AND(I28>Assumptions!C48,G29>Assumptions!C47),Assumptions!C14,0) -> 512.44 | K41: =(1-Assumptions!C31)*(1-Assumptions!C34)*Assumptions!C37 -> 0.14828766 | L41: =(IF(E27>Assumptions!C46,Assumptions!C12*EXP(-Assumptions!C20*Assumptions!C23),0)+IF(G29>Assumptions!C47,Assumptions!C13*EXP(-Assumptions!C20*Assumptions!C24),0)+IF(AND(I28>Assumptions!C48,G29>Assumptions!C47),Assumptions!C14*EXP(-Assumptions!C20*Assumptions!C25),0))*(1-Assumptions!C31)*(1-Assumptions!C34)*Assumptions!C37 -> 74.29788
B42: DDD | C42: Down-Down-Down | D42: =E27 -> 1744.3793 | E42: =IF(E27>Assumptions!C46,"YES","NO") -> YES | F42: =G29 -> 731.08351 | G42: =IF(G29>Assumptions!C47,"YES","NO") -> NO | H42: =I30 -> 421.79849 | I42: =IF(AND(I30>Assumptions!C48,G29>Assumptions!C47),"YES","NO") -> NO | J42: =IF(E27>Assumptions!C46,Assumptions!C12,0)+IF(G29>Assumptions!C47,Assumptions!C13,0)+IF(AND(I30>Assumptions!C48,G29>Assumptions!C47),Assumptions!C14,0) -> 512.44 | K42: =(1-Assumptions!C31)*(1-Assumptions!C34)*(1-Assumptions!C37) -> 0.21724959 | L42: =(IF(E27>Assumptions!C46,Assumptions!C12*EXP(-Assumptions!C20*Assumptions!C23),0)+IF(G29>Assumptions!C47,Assumptions!C13*EXP(-Assumptions!C20*Assumptions!C24),0)+IF(AND(I30>Assumptions!C48,G29>Assumptions!C47),Assumptions!C14*EXP(-Assumptions!C20*Assumptions!C25),0))*(1-Assumptions!C31)*(1-Assumptions!C34)*(1-Assumptions!C37) -> 108.85048
B43: Σ Probabilities (must = 100%) | K43: =SUM(K35:K42) -> 1
B45: STEP 3 — CVR FAIR VALUE (Sum of probability-weighted discounted payoffs)
...

Sheet Deal Valuation
B1: PFIZER – METSERA: M&A DEAL VALUATION SUMMARY
B3: CONSIDERATION COMPONENT | C3: Nominal ($mn) | D3: Fair Value ($mn) | E3: % of Total FV
B4: Cash consideration | C4: =Assumptions!C5*Assumptions!C4 -> 7307.84 | D4: =Assumptions!C5*Assumptions!C4 -> 7307.84 | E4: =D4/D10 -> 0.82807421
B5: CVR – Milestone 1 ($4.60/sh) | C5: =Assumptions!C12 -> 512.44 | D5: =C5/$C$8*$D$8 -> 232.17475
B6: CVR – Milestone 2 ($6.40/sh) | C6: =Assumptions!C13 -> 712.96 | D6: =C6/$C$8*$D$8 -> 323.02574
B7: CVR – Milestone 3 ($9.65/sh) | C7: =Assumptions!C14 -> 1075.01 | D7: =C7/$C$8*$D$8 -> 487.06226
B8: Total CVR (nominal / fair value from binomial tree) | C8: =SUM(C5:C7) -> 2300.41 | D8: ='CVR Binomial Tree'!F46 -> 1042.2628 | E8: =D8/D10 -> 0.11810205
B9: Employee stock awards | C9: =Assumptions!C16 -> 475 | D9: =Assumptions!C16 -> 475 | E9: =D9/D10 -> 0.053823736
B10: TOTAL CONSIDERATION | C10: =C4+C8+C9 -> 10083.25 | D10: =D4+D8+D9 -> 8825.1028 | E10: =D10/D10 -> 1
B12: KEY DEAL METRICS
B13: EV / Peak Sales (2030E, est.) | D13: =D10/('Metsera rNPV'!C9*1000) -> 1.4869223
B14: CVR Nominal / Cash EV (%) | D14: =Assumptions!C8/(Assumptions!C5*Assumptions!C4) -> 0.31473048
B15: CVR Fair Value as % of Total Deal (%) | D15: ='CVR Binomial Tree'!F46/D10 -> 0.11810205
B16: CVR Implied Prob — Pfizer stated FV (%) | D16: =Assumptions!C15/Assumptions!C8 -> 0.27478261
B17: CVR Implied Prob — This Binomial Model (%) | D17: ='CVR Binomial Tree'!F46/Assumptions!C8 -> 0.45315772
B18: Pfizer 2030E Net Revenue ($mn) | D18: ='Pfizer Financials'!J6 -> 56282
B19: Patent Cliff Revenue at Risk ($mn) | D19: 17000
B20: Metsera Peak Sales / Patent Cliff Risk | D20: ='Metsera rNPV'!C9*1000/D19 -> 0.3491263
B21: CVR_M2_prob helper → | C21: =Assumptions!C41 -> 0.62
B22: CVR_M3_prob helper → | C22: =Assumptions!C43 -> 0.341

Sheet Sensitivity
B1: SENSITIVITY ANALYSIS — CVR FAIR VALUE ($mn)
B2: Table 1: CVR Fair Value vs. Milestone 2 Success Probability (P₂, x-axis) and Drug Program Volatility σ (y-axis). All other inputs from Assumptions sheet. Pfizer stated value: $632mn highlighted.
B3: σ (volatility) →
B4: CVR Fair Value ($mn) | C4: P(M2): FDA Approval Probability — Monotherapy
C5: 0.35 | D5: 0.4 | E5: 0.45 | F5: 0.5 | G5: 0.55 | H5: 0.6 | I5: 0.65 | J5: 0.7 | K5: 0.75 | L5: 0.8 | M5: 0.85 | N5: 0.9
B6: σ (volatility) ↓
B7: 0.3 | C7: =Assumptions!C13*Assumptions!C40*EXP(-Assumptions!C20*Assumptions!C23)+Assumptions!C14*0.35*EXP(-Assumptions!C20*Assumptions!C24)+Assumptions!C15*0.35*Assumptions!C42*EXP(-Assumptions!C20*Assumptions!C25) -> 1022.8905 | D7: =Assumptions!C13*Assumptions!C40*EXP(-Assumptions!C20*Assumptions!C23)+Assumptions!C14*0.4*EXP(-Assumptions!C20*Assumptions!C24)+Assumptions!C15*0.4*Assumptions!C42*EXP(-Assumptions!C20*Assumptions!C25) -> 1084.3702 | E7: =Assumptions!C13*Assumptions!C40*EXP(-Assumptions!C20*Assumptions!C23)+Assumptions!C14*0.45*EXP(-Assumptions!C20*Assumptions!C24)+Assumptions!C15*0.45*Assumptions!C42*EXP(-Assumptions!C20*Assumptions!C25) -> 1145.8499 | F7: =Assumptions!C13*Assumptions!C40*EXP(-Assumptions!C20*Assumptions!C23)+Assumptions!C14*0.5*EXP(-Assumptions!C20*Assumptions!C24)+Assumptions!C15*0.5*Assumptions!C42*EXP(-Assumptions!C20*Assumptions!C25) -> 1207.3295 | G7: =Assumptions!C13*Assumptions!C40*EXP(-Assumptions!C20*Assumptions!C23)+Assumptions!C14*0.55*EXP(-Assumptions!C20*Assumptions!C24)+Assumptions!C15*0.55*Assumptions!C42*EXP(-Assumptions!C20*Assumptions!C25) -> 1268.8092 | H7: =Assumptions!C13*Assumptions!C40*EXP(-Assumptions!C20*Assumptions!C23)+Assumptions!C14*0.6*EXP(-Assumptions!C20*Assumptions!C24)+Assumptions!C15*0.6*Assumptions!C42*EXP(-Assumptions!C20*Assumptions!C25) -> 1330.2889 | I7: =Assumptions!C13*Assumptions!C40*EXP(-Assumptions!C20*Assumptions!C23)+Assumptions!C14*0.65*EXP(-Assumptions!C20*Assumptions!C24)+Assumptions!C15*0.65*Assumptions!C42*EXP(-Assumptions!C20*Assumptions!C25) -> 1391.7685 | J7: =Assumptions!C13*Assumptions!C40*EXP(-Assumptions!C20*Assumptions!C23)+Assumptions!C14*0.7*EXP(-Assumptions!C20*Assumptions!C24)+Assumptions!C15*0.7*Assumptions!C42*EXP(-Assumptions!C20*Assumptions!C25) -> 1453.2482 | K7: =Assumptions!C13*Assumptions!C40*EXP(-Assumptions!C20*Assumptions!C23)+Assumptions!C14*0.75*EXP(-Assumptions!C20*Assumptions!C24)+Assumptions!C15*0.75*Assumptions!C42*EXP(-Assumptions!C20*Assumptions!C25) -> 1514.7278 | L7: =Assumptions!C13*Assumptions!C40*EXP(-Assumptions!C20*Assumptions!C23)+Assumptions!C14*0.8*EXP(-Assumptions!C20*Assumptions!C24)+Assumptions!C15*0.8*Assumptions!C42*EXP(-Assumptions!C20*Assumptions!C25) -> 1576.2075 | M7: =Assumptions!C13*Assumptions!C40*EXP(-Assumptions!C20*Assumptions!C23)+Assumptions!C14*0.85*EXP(-Assumptions!C20*Assumptions!C24)+Assumptions!C15*0.85*Assumptions!C42*EXP(-Assumptions!C20*Assumptions!C25) -> 1637.6872 | N7: =Assumptions!C13*Assumptions!C40*EXP(-Assumptions!C20*Assumptions!C23)+Assumptions!C14*0.9*EXP(-Assumptions!C20*Assumptions!C24)+Assumptions!C15*0.9*Assumptions!C42*EXP(-Assumptions!C20*Assumptions!C25) -> 1699.1668
B8: 0.35 | C8: =Assumptions!C13*Assumptions!C40*EXP(-Assumptions!C20*Assumptions!C23)+Assumptions!C14*0.35*EXP(-Assumptions!C20*Assumptions!C24)+Assumptions!C15*0.35*Assumptions!C42*EXP(-Assumptions!C20*Assumptions!C25) -> 1022.8905 | D8: =Assumptions!C13*Assumptions!C40*EXP(-Assumptions!C20*Assumptions!C23)+Assumptions!C14*0.4*EXP(-Assumptions!C20*Assumptions!C24)+Assumptions!C15*0.4*Assumptions!C42*EXP(-Assumptions!C20*Assumptions!C25) -> 1084.3702 | E8: =Assumptions!C13*Assumptions!C40*EXP(-Assumptions!C20*Assumptions!C23)+Assumptions!C14*0.45*EXP(-Assumptions!C20*Assumptions!C24)+Assumptions!C15*0.45*Assumptions!C42*EXP(-Assumptions!C20*Assumptions!C25) -> 1145.8499 | F8: =Assumptions!C13*Assumptions!C40*EXP(-Assumptions!C20*Assumptions!C23)+Assumptions!C14*0.5*EXP(-Assumptions!C20*Assumptions!C24)+Assumptions!C15*0.5*Assumptions!C42*EXP(-Assumptions!C20*Assumptions!C25) -> 1207.3295 | G8: =Assumptions!C13*Assumptions!C40*EXP(-Assumptions!C20*Assumptions!C23)+Assumptions!C14*0.55*EXP(-Assumptions!C20*Assumptions!C24)+Assumptions!C15*0.55*Assumptions!C42*EXP(-Assumptions!C20*Assumptions!C25) -> 1268.8092 | H8: =Assumptions!C13*Assumptions!C40*EXP(-Assumptions!C20*Assumptions!C23)+Assumptions!C14*0.6*EXP(-Assumptions!C20*Assumptions!C24)+Assumptions!C15*0.6*Assumptions!C42*EXP(-Assumptions!C20*Assumptions!C25) -> 1330.2889 | I8: =Assumptions!C13*Assumptions!C40*EXP(-Assumptions!C20*Assumptions!C23)+Assumptions!C14*0.65*EXP(-Assumptions!C20*Assumptions!C24)+Assumptions!C15*0.65*Assumptions!C42*EXP(-Assumptions!C20*Assumptions!C25) -> 1391.7685 | J8: =Assumptions!C13*Assumptions!C40*EXP(-Assumptions!C20*Assumptions!C23)+Assumptions!C14*0.7*EXP(-Assumptions!C20*Assumptions!C24)+Assumptions!C15*0.7*Assumptions!C42*EXP(-Assumptions!C20*Assumptions!C25) -> 1453.2482 | K8: =Assumptions!C13*Assumptions!C40*EXP(-Assumptions!C20*Assumptions!C23)+Assumptions!C14*0.75*EXP(-Assumptions!C20*Assumptions!C24)+Assumptions!C15*0.75*Assumptions!C42*EXP(-Assumptions!C20*Assumptions!C25) -> 1514.7278 | L8: =Assumptions!C13*Assumptions!C40*EXP(-Assumptions!C20*Assumptions!C23)+Assumptions!C14*0.8*EXP(-Assumptions!C20*Assumptions!C24)+Assumptions!C15*0.8*Assumptions!C42*EXP(-Assumptions!C20*Assumptions!C25) -> 1576.2075 | M8: =Assumptions!C13*Assumptions!C40*EXP(-Assumptions!C20*Assumptions!C23)+Assumptions!C14*0.85*EXP(-Assumptions!C20*Assumptions!C24)+Assumptions!C15*0.85*Assumptions!C42*EXP(-Assumptions!C20*Assumptions!C25) -> 1637.6872 | N8: =Assumptions!C13*Assumptions!C40*EXP(-Assumptions!C20*Assumptions!C23)+Assumptions!C14*0.9*EXP(-Assumptions!C20*Assumptions!C24)+Assumptions!C15*0.9*Assumptions!C42*EXP(-Assumptions!C20*Assumptions!C25) -> 1699.1668
B9: 0.4 | C9: =Assumptions!C13*Assumptions!C40*EXP(-Assumptions!C20*Assumptions!C23)+Assumptions!C14*0.35*EXP(-Assumptions!C20*Assumptions!C24)+Assumptions!C15*0.35*Assumptions!C42*EXP(-Assumptions!C20*Assumptions!C25) -> 1022.8905 | D9: =Assumptions!C13*Assumptions!C40*EXP(-Assumptions!C20*Assumptions!C23)+Assumptions!C14*0.4*EXP(-Assumptions!C20*Assumptions!C24)+Assumptions!C15*0.4*Assumptions!C42*EXP(-Assumptions!C20*Assumptions!C25) -> 1084.3702 | E9: =Assumptions!C13*Assumptions!C40*EXP(-Assumptions!C20*Assumptions!C23)+Assumptions!C14*0.45*EXP(-Assumptions!C20*Assumptions!C24)+Assumptions!C15*0.45*Assumptions!C42*EXP(-Assumptions!C20*Assumptions!C25) -> 1145.8499 | F9: =Assumptions!C13*Assumptions!C40*EXP(-Assumptions!C20*Assumptions!C23)+Assumptions!C14*0.5*EXP(-Assumptions!C20*Assumptions!C24)+Assumptions!C15*0.5*Assumptions!C42*EXP(-Assumptions!C20*Assumptions!C25) -> 1207.3295 | G9: =Assumptions!C13*Assumptions!C40*EXP(-Assumptions!C20*Assumptions!C23)+Assumptions!C14*0.55*EXP(-Assumptions!C20*Assumptions!C24)+Assumptions!C15*0.55*Assumptions!C42*EXP(-Assumptions!C20*Assumptions!C25) -> 1268.8092 | H9: =Assumptions!C13*Assumptions!C40*EXP(-Assumptions!C20*Assumptions!C23)+Assumptions!C14*0.6*EXP(-Assumptions!C20*Assumptions!C24)+Assumptions!C15*0.6*Assumptions!C42*EXP(-Assumptions!C20*Assumptions!C25) -> 1330.2889 | I9: =Assumptions!C13*Assumptions!C40*EXP(-Assumptions!C20*Assumptions!C23)+Assumptions!C14*0.65*EXP(-Assumptions!C20*Assumptions!C24)+Assumptions!C15*0.65*Assumptions!C42*EXP(-Assumptions!C20*Assumptions!C25) -> 1391.7685 | J9: =Assumptions!C13*Assumptions!C40*EXP(-Assumptions!C20*Assumptions!C23)+Assumptions!C14*0.7*EXP(-Assumptions!C20*Assumptions!C24)+Assumptions!C15*0.7*Assumptions!C42*EXP(-Assumptions!C20*Assumptions!C25) -> 1453.2482 | K9: =Assumptions!C13*Assumptions!C40*EXP(-Assumptions!C20*Assumptions!C23)+Assumptions!C14*0.75*EXP(-Assumptions!C20*Assumptions!C24)+Assumptions!C15*0.75*Assumptions!C42*EXP(-Assumptions!C20*Assumptions!C25) -> 1514.7278 | L9: =Assumptions!C13*Assumptions!C40*EXP(-Assumptions!C20*Assumptions!C23)+Assumptions!C14*0.8*EXP(-Assumptions!C20*Assumptions!C24)+Assumptions!C15*0.8*Assumptions!C42*EXP(-Assumptions!C20*Assumptions!C25) -> 1576.2075 | M9: =Assumptions!C13*Assumptions!C40*EXP(-Assumptions!C20*Assumptions!C23)+Assumptions!C14*0.85*EXP(-Assumptions!C20*Assumptions!C24)+Assumptions!C15*0.85*Assumptions!C42*EXP(-Assumptions!C20*Assumptions!C25) -> 1637.6872 | N9: =Assumptions!C13*Assumptions!C40*EXP(-Assumptions!C20*Assumptions!C23)+Assumptions!C14*0.9*EXP(-Assumptions!C20*Assumptions!C24)+Assumptions!C15*0.9*Assumptions!C42*EXP(-Assumptions!C20*Assumptions!C25) -> 1699.1668
B10: 0.45 | C10: =Assumptions!C13*Assumptions!C40*EXP(-Assumptions!C20*Assumptions!C23)+Assumptions!C14*0.35*EXP(-Assumptions!C20*Assumptions!C24)+Assumptions!C15*0.35*Assumptions!C42*EXP(-Assumptions!C20*Assumptions!C25) -> 1022.8905 | D10: =Assumptions!C13*Assumptions!C40*EXP(-Assumptions!C20*Assumptions!C23)+Assumptions!C14*0.4*EXP(-Assumptions!C20*Assumptions!C24)+Assumptions!C15*0.4*Assumptions!C42*EXP(-Assumptions!C20*Assumptions!C25) -> 1084.3702 | E10: =Assumptions!C13*Assumptions!C40*EXP(-Assumptions!C20*Assumptions!C23)+Assumptions!C14*0.45*EXP(-Assumptions!C20*Assumptions!C24)+Assumptions!C15*0.45*Assumptions!C42*EXP(-Assumptions!C20*Assumptions!C25) -> 1145.8499 | F10: =Assumptions!C13*Assumptions!C40*EXP(-Assumptions!C20*Assumptions!C23)+Assumptions!C14*0.5*EXP(-Assumptions!C20*Assumptions!C24)+Assumptions!C15*0.5*Assumptions!C42*EXP(-Assumptions!C20*Assumptions!C25) -> 1207.3295 | G10: =Assumptions!C13*Assumptions!C40*EXP(-Assumptions!C20*Assumptions!C23)+Assumptions!C14*0.55*EXP(-Assumptions!C20*Assumptions!C24)+Assumptions!C15*0.55*Assumptions!C42*EXP(-Assumptions!C20*Assumptions!C25) -> 1268.8092 | H10: =Assumptions!C13*Assumptions!C40*EXP(-Assumptions!C20*Assumptions!C23)+Assumptions!C14*0.6*EXP(-Assumptions!C20*Assumptions!C24)+Assumptions!C15*0.6*Assumptions!C42*EXP(-Assumptions!C20*Assumptions!C25) -> 1330.2889 | I10: =Assumptions!C13*Assumptions!C40*EXP(-Assumptions!C20*Assumptions!C23)+Assumptions!C14*0.65*EXP(-Assumptions!C20*Assumptions!C24)+Assumptions!C15*0.65*Assumptions!C42*EXP(-Assumptions!C20*Assumptions!C25) -> 1391.7685 | J10: =Assumptions!C13*Assumptions!C40*EXP(-Assumptions!C20*Assumptions!C23)+Assumptions!C14*0.7*EXP(-Assumptions!C20*Assumptions!C24)+Assumptions!C15*0.7*Assumptions!C42*EXP(-Assumptions!C20*Assumptions!C25) -> 1453.2482 | K10: =Assumptions!C13*Assumptions!C40*EXP(-Assumptions!C20*Assumptions!C23)+Assumptions!C14*0.75*EXP(-Assumptions!C20*Assumptions!C24)+Assumptions!C15*0.75*Assumptions!C42*EXP(-Assumptions!C20*Assumptions!C25) -> 1514.7278 | L10: =Assumptions!C13*Assumptions!C40*EXP(-Assumptions!C20*Assumptions!C23)+Assumptions!C14*0.8*EXP(-Assumptions!C20*Assumptions!C24)+Assumptions!C15*0.8*Assumptions!C42*EXP(-Assumptions!C20*Assumptions!C25) -> 1576.2075 | M10: =Assumptions!C13*Assumptions!C40*EXP(-Assumptions!C20*Assumptions!C23)+Assumptions!C14*0.85*EXP(-Assumptions!C20*Assumptions!C24)+Assumptions!C15*0.85*Assumptions!C42*EXP(-Assumptions!C20*Assumptions!C25) -> 1637.6872 | N10: =Assumptions!C13*Assumptions!C40*EXP(-Assumptions!C20*Assumptions!C23)+Assumptions!C14*0.9*EXP(-Assumptions!C20*Assumptions!C24)+Assumptions!C15*0.9*Assumptions!C42*EXP(-Assumptions!C20*Assumptions!C25) -> 1699.1668
B11: 0.5 | C11: =Assumptions!C13*Assumptions!C40*EXP(-Assumptions!C20*Assumptions!C23)+Assumptions!C14*0.35*EXP(-Assumptions!C20*Assumptions!C24)+Assumptions!C15*0.35*Assumptions!C42*EXP(-Assumptions!C20*Assumptions!C25) -> 1022.8905 | D11: =Assumptions!C13*Assumptions!C40*EXP(-Assumptions!C20*Assumptions!C23)+Assumptions!C14*0.4*EXP(-Assumptions!C20*Assumptions!C24)+Assumptions!C15*0.4*Assumptions!C42*EXP(-Assumptions!C20*Assumptions!C25) -> 1084.3702 | E11: =Assumptions!C13*Assumptions!C40*EXP(-Assumptions!C20*Assumptions!C23)+Assumptions!C14*0.45*EXP(-Assumptions!C20*Assumptions!C24)+Assumptions!C15*0.45*Assumptions!C42*EXP(-Assumptions!C20*Assumptions!C25) -> 1145.8499 | F11: =Assumptions!C13*Assumptions!C40*EXP(-Assumptions!C20*Assumptions!C23)+Assumptions!C14*0.5*EXP(-Assumptions!C20*Assumptions!C24)+Assumptions!C15*0.5*Assumptions!C42*EXP(-Assumptions!C20*Assumptions!C25) -> 1207.3295 | G11: =Assumptions!C13*Assumptions!C40*EXP(-Assumptions!C20*Assumptions!C23)+Assumptions!C14*0.55*EXP(-Assumptions!C20*Assumptions!C24)+Assumptions!C15*0.55*Assumptions!C42*EXP(-Assumptions!C20*Assumptions!C25) -> 1268.8092 | H11: =Assumptions!C13*Assumptions!C40*EXP(-Assumptions!C20*Assumptions!C23)+Assumptions!C14*0.6*EXP(-Assumptions!C20*Assumptions!C24)+Assumptions!C15*0.6*Assumptions!C42*EXP(-Assumptions!C20*Assumptions!C25) -> 1330.2889 | I11: =Assumptions!C13*Assumptions!C40*EXP(-Assumptions!C20*Assumptions!C23)+Assumptions!C14*0.65*EXP(-Assumptions!C20*Assumptions!C24)+Assumptions!C15*0.65*Assumptions!C42*EXP(-Assumptions!C20*Assumptions!C25) -> 1391.7685 | J11: =Assumptions!C13*Assumptions!C40*EXP(-Assumptions!C20*Assumptions!C23)+Assumptions!C14*0.7*EXP(-Assumptions!C20*Assumptions!C24)+Assumptions!C15*0.7*Assumptions!C42*EXP(-Assumptions!C20*Assumptions!C25) -> 1453.2482 | K11: =Assumptions!C13*Assumptions!C40*EXP(-Assumptions!C20*Assumptions!C23)+Assumptions!C14*0.75*EXP(-Assumptions!C20*Assumptions!C24)+Assumptions!C15*0.75*Assumptions!C42*EXP(-Assumptions!C20*Assumptions!C25) -> 1514.7278 | L11: =Assumptions!C13*Assumptions!C40*EXP(-Assumptions!C20*Assumptions!C23)+Assumptions!C14*0.8*EXP(-Assumptions!C20*Assumptions!C24)+Assumptions!C15*0.8*Assumptions!C42*EXP(-Assumptions!C20*Assumptions!C25) -> 1576.2075 | M11: =Assumptions!C13*Assumptions!C40*EXP(-Assumptions!C20*Assumptions!C23)+Assumptions!C14*0.85*EXP(-Assumptions!C20*Assumptions!C24)+Assumptions!C15*0.85*Assumptions!C42*EXP(-Assumptions!C20*Assumptions!C25) -> 1637.6872 | N11: =Assumptions!C13*Assumptions!C40*EXP(-Assumptions!C20*Assumptions!C23)+Assumptions!C14*0.9*EXP(-Assumptions!C20*Assumptions!C24)+Assumptions!C15*0.9*Assumptions!C42*EXP(-Assumptions!C20*Assumptions!C25) -> 1699.1668
B12: 0.55 | C12: =Assumptions!C13*Assumptions!C40*EXP(-Assumptions!C20*Assumptions!C23)+Assumptions!C14*0.35*EXP(-Assumptions!C20*Assumptions!C24)+Assumptions!C15*0.35*Assumptions!C42*EXP(-Assumptions!C20*Assumptions!C25) -> 1022.8905 | D12: =Assumptions!C13*Assumptions!C40*EXP(-Assumptions!C20*Assumptions!C23)+Assumptions!C14*0.4*EXP(-Assumptions!C20*Assumptions!C24)+Assumptions!C15*0.4*Assumptions!C42*EXP(-Assumptions!C20*Assumptions!C25) -> 1084.3702 | E12: =Assumptions!C13*Assumptions!C40*EXP(-Assumptions!C20*Assumptions!C23)+Assumptions!C14*0.45*EXP(-Assumptions!C20*Assumptions!C24)+Assumptions!C15*0.45*Assumptions!C42*EXP(-Assumptions!C20*Assumptions!C25) -> 1145.8499 | F12: =Assumptions!C13*Assumptions!C40*EXP(-Assumptions!C20*Assumptions!C23)+Assumptions!C14*0.5*EXP(-Assumptions!C20*Assumptions!C24)+Assumptions!C15*0.5*Assumptions!C42*EXP(-Assumptions!C20*Assumptions!C25) -> 1207.3295 | G12: =Assumptions!C13*Assumptions!C40*EXP(-Assumptions!C20*Assumptions!C23)+Assumptions!C14*0.55*EXP(-Assumptions!C20*Assumptions!C24)+Assumptions!C15*0.55*Assumptions!C42*EXP(-Assumptions!C20*Assumptions!C25) -> 1268.8092 | H12: =Assumptions!C13*Assumptions!C40*EXP(-Assumptions!C20*Assumptions!C23)+Assumptions!C14*0.6*EXP(-Assumptions!C20*Assumptions!C24)+Assumptions!C15*0.6*Assumptions!C42*EXP(-Assumptions!C20*Assumptions!C25) -> 1330.2889 | I12: =Assumptions!C13*Assumptions!C40*EXP(-Assumptions!C20*Assumptions!C23)+Assumptions!C14*0.65*EXP(-Assumptions!C20*Assumptions!C24)+Assumptions!C15*0.65*Assumptions!C42*EXP(-Assumptions!C20*Assumptions!C25) -> 1391.7685 | J12: =Assumptions!C13*Assumptions!C40*EXP(-Assumptions!C20*Assumptions!C23)+Assumptions!C14*0.7*EXP(-Assumptions!C20*Assumptions!C24)+Assumptions!C15*0.7*Assumptions!C42*EXP(-Assumptions!C20*Assumptions!C25) -> 1453.2482 | K12: =Assumptions!C13*Assumptions!C40*EXP(-Assumptions!C20*Assumptions!C23)+Assumptions!C14*0.75*EXP(-Assumptions!C20*Assumptions!C24)+Assumptions!C15*0.75*Assumptions!C42*EXP(-Assumptions!C20*Assumptions!C25) -> 1514.7278 | L12: =Assumptions!C13*Assumptions!C40*EXP(-Assumptions!C20*Assumptions!C23)+Assumptions!C14*0.8*EXP(-Assumptions!C20*Assumptions!C24)+Assumptions!C15*0.8*Assumptions!C42*EXP(-Assumptions!C20*Assumptions!C25) -> 1576.2075 | M12: =Assumptions!C13*Assumptions!C40*EXP(-Assumptions!C20*Assumptions!C23)+Assumptions!C14*0.85*EXP(-Assumptions!C20*Assumptions!C24)+Assumptions!C15*0.85*Assumptions!C42*EXP(-Assumptions!C20*Assumptions!C25) -> 1637.6872 | N12: =Assumptions!C13*Assumptions!C40*EXP(-Assumptions!C20*Assumptions!C23)+Assumptions!C14*0.9*EXP(-Assumptions!C20*Assumptions!C24)+Assumptions!C15*0.9*Assumptions!C42*EXP(-Assumptions!C20*Assumptions!C25) -> 1699.1668
B13: 0.6 | C13: =Assumptions!C13*Assumptions!C40*EXP(-Assumptions!C20*Assumptions!C23)+Assumptions!C14*0.35*EXP(-Assumptions!C20*Assumptions!C24)+Assumptions!C15*0.35*Assumptions!C42*EXP(-Assumptions!C20*Assumptions!C25) -> 1022.8905 | D13: =Assumptions!C13*Assumptions!C40*EXP(-Assumptions!C20*Assumptions!C23)+Assumptions!C14*0.4*EXP(-Assumptions!C20*Assumptions!C24)+Assumptions!C15*0.4*Assumptions!C42*EXP(-Assumptions!C20*Assumptions!C25) -> 1084.3702 | E13: =Assumptions!C13*Assumptions!C40*EXP(-Assumptions!C20*Assumptions!C23)+Assumptions!C14*0.45*EXP(-Assumptions!C20*Assumptions!C24)+Assumptions!C15*0.45*Assumptions!C42*EXP(-Assumptions!C20*Assumptions!C25) -> 1145.8499 | F13: =Assumptions!C13*Assumptions!C40*EXP(-Assumptions!C20*Assumptions!C23)+Assumptions!C14*0.5*EXP(-Assumptions!C20*Assumptions!C24)+Assumptions!C15*0.5*Assumptions!C42*EXP(-Assumptions!C20*Assumptions!C25) -> 1207.3295 | G13: =Assumptions!C13*Assumptions!C40*EXP(-Assumptions!C20*Assumptions!C23)+Assumptions!C14*0.55*EXP(-Assumptions!C20*Assumptions!C24)+Assumptions!C15*0.55*Assumptions!C42*EXP(-Assumptions!C20*Assumptions!C25) -> 1268.8092 | H13: =Assumptions!C13*Assumptions!C40*EXP(-Assumptions!C20*Assumptions!C23)+Assumptions!C14*0.6*EXP(-Assumptions!C20*Assumptions!C24)+Assumptions!C15*0.6*Assumptions!C42*EXP(-Assumptions!C20*Assumptions!C25) -> 1330.2889 | I13: =Assumptions!C13*Assumptions!C40*EXP(-Assumptions!C20*Assumptions!C23)+Assumptions!C14*0.65*EXP(-Assumptions!C20*Assumptions!C24)+Assumptions!C15*0.65*Assumptions!C42*EXP(-Assumptions!C20*Assumptions!C25) -> 1391.7685 | J13: =Assumptions!C13*Assumptions!C40*EXP(-Assumptions!C20*Assumptions!C23)+Assumptions!C14*0.7*EXP(-Assumptions!C20*Assumptions!C24)+Assumptions!C15*0.7*Assumptions!C42*EXP(-Assumptions!C20*Assumptions!C25) -> 1453.2482 | K13: =Assumptions!C13*Assumptions!C40*EXP(-Assumptions!C20*Assumptions!C23)+Assumptions!C14*0.75*EXP(-Assumptions!C20*Assumptions!C24)+Assumptions!C15*0.75*Assumptions!C42*EXP(-Assumptions!C20*Assumptions!C25) -> 1514.7278 | L13: =Assumptions!C13*Assumptions!C40*EXP(-Assumptions!C20*Assumptions!C23)+Assumptions!C14*0.8*EXP(-Assumptions!C20*Assumptions!C24)+Assumptions!C15*0.8*Assumptions!C42*EXP(-Assumptions!C20*Assumptions!C25) -> 1576.2075 | M13: =Assumptions!C13*Assumptions!C40*EXP(-Assumptions!C20*Assumptions!C23)+Assumptions!C14*0.85*EXP(-Assumptions!C20*Assumptions!C24)+Assumptions!C15*0.85*Assumptions!C42*EXP(-Assumptions!C20*Assumptions!C25) -> 1637.6872 | N13: =Assumptions!C13*Assumptions!C40*EXP(-Assumptions!C20*Assumptions!C23)+Assumptions!C14*0.9*EXP(-Assumptions!C20*Assumptions!C24)+Assumptions!C15*0.9*Assumptions!C42*EXP(-Assumptions!C20*Assumptions!C25) -> 1699.1668
B14: 0.65 | C14: =Assumptions!C13*Assumptions!C40*EXP(-Assumptions!C20*Assumptions!C23)+Assumptions!C14*0.35*EXP(-Assumptions!C20*Assumptions!C24)+Assumptions!C15*0.35*Assumptions!C42*EXP(-Assumptions!C20*Assumptions!C25) -> 1022.8905 | D14: =Assumptions!C13*Assumptions!C40*EXP(-Assumptions!C20*Assumptions!C23)+Assumptions!C14*0.4*EXP(-Assumptions!C20*Assumptions!C24)+Assumptions!C15*0.4*Assumptions!C42*EXP(-Assumptions!C20*Assumptions!C25) -> 1084.3702 | E14: =Assumptions!C13*Assumptions!C40*EXP(-Assumptions!C20*Assumptions!C23)+Assumptions!C14*0.45*EXP(-Assumptions!C20*Assumptions!C24)+Assumptions!C15*0.45*Assumptions!C42*EXP(-Assumptions!C20*Assumptions!C25) -> 1145.8499 | F14: =Assumptions!C13*Assumptions!C40*EXP(-Assumptions!C20*Assumptions!C23)+Assumptions!C14*0.5*EXP(-Assumptions!C20*Assumptions!C24)+Assumptions!C15*0.5*Assumptions!C42*EXP(-Assumptions!C20*Assumptions!C25) -> 1207.3295 | G14: =Assumptions!C13*Assumptions!C40*EXP(-Assumptions!C20*Assumptions!C23)+Assumptions!C14*0.55*EXP(-Assumptions!C20*Assumptions!C24)+Assumptions!C15*0.55*Assumptions!C42*EXP(-Assumptions!C20*Assumptions!C25) -> 1268.8092 | H14: =Assumptions!C13*Assumptions!C40*EXP(-Assumptions!C20*Assumptions!C23)+Assumptions!C14*0.6*EXP(-Assumptions!C20*Assumptions!C24)+Assumptions!C15*0.6*Assumptions!C42*EXP(-Assumptions!C20*Assumptions!C25) -> 1330.2889 | I14: =Assumptions!C13*Assumptions!C40*EXP(-Assumptions!C20*Assumptions!C23)+Assumptions!C14*0.65*EXP(-Assumptions!C20*Assumptions!C24)+Assumptions!C15*0.65*Assumptions!C42*EXP(-Assumptions!C20*Assumptions!C25) -> 1391.7685 | J14: =Assumptions!C13*Assumptions!C40*EXP(-Assumptions!C20*Assumptions!C23)+Assumptions!C14*0.7*EXP(-Assumptions!C20*Assumptions!C24)+Assumptions!C15*0.7*Assumptions!C42*EXP(-Assumptions!C20*Assumptions!C25) -> 1453.2482 | K14: =Assumptions!C13*Assumptions!C40*EXP(-Assumptions!C20*Assumptions!C23)+Assumptions!C14*0.75*EXP(-Assumptions!C20*Assumptions!C24)+Assumptions!C15*0.75*Assumptions!C42*EXP(-Assumptions!C20*Assumptions!C25) -> 1514.7278 | L14: =Assumptions!C13*Assumptions!C40*EXP(-Assumptions!C20*Assumptions!C23)+Assumptions!C14*0.8*EXP(-Assumptions!C20*Assumptions!C24)+Assumptions!C15*0.8*Assumptions!C42*EXP(-Assumptions!C20*Assumptions!C25) -> 1576.2075 | M14: =Assumptions!C13*Assumptions!C40*EXP(-Assumptions!C20*Assumptions!C23)+Assumptions!C14*0.85*EXP(-Assumptions!C20*Assumptions!C24)+Assumptions!C15*0.85*Assumptions!C42*EXP(-Assumptions!C20*Assumptions!C25) -> 1637.6872 | N14: =Assumptions!C13*Assumptions!C40*EXP(-Assumptions!C20*Assumptions!C23)+Assumptions!C14*0.9*EXP(-Assumptions!C20*Assumptions!C24)+Assumptions!C15*0.9*Assumptions!C42*EXP(-Assumptions!C20*Assumptions!C25) -> 1699.1668
B15: 0.7 | C15: =Assumptions!C13*Assumptions!C40*EXP(-Assumptions!C20*Assumptions!C23)+Assumptions!C14*0.35*EXP(-Assumptions!C20*Assumptions!C24)+Assumptions!C15*0.35*Assumptions!C42*EXP(-Assumptions!C20*Assumptions!C25) -> 1022.8905 | D15: =Assumptions!C13*Assumptions!C40*EXP(-Assumptions!C20*Assumptions!C23)+Assumptions!C14*0.4*EXP(-Assumptions!C20*Assumptions!C24)+Assumptions!C15*0.4*Assumptions!C42*EXP(-Assumptions!C20*Assumptions!C25) -> 1084.3702 | E15: =Assumptions!C13*Assumptions!C40*EXP(-Assumptions!C20*Assumptions!C23)+Assumptions!C14*0.45*EXP(-Assumptions!C20*Assumptions!C24)+Assumptions!C15*0.45*Assumptions!C42*EXP(-Assumptions!C20*Assumptions!C25) -> 1145.8499 | F15: =Assumptions!C13*Assumptions!C40*EXP(-Assumptions!C20*Assumptions!C23)+Assumptions!C14*0.5*EXP(-Assumptions!C20*Assumptions!C24)+Assumptions!C15*0.5*Assumptions!C42*EXP(-Assumptions!C20*Assumptions!C25) -> 1207.3295 | G15: =Assumptions!C13*Assumptions!C40*EXP(-Assumptions!C20*Assumptions!C23)+Assumptions!C14*0.55*EXP(-Assumptions!C20*Assumptions!C24)+Assumptions!C15*0.55*Assumptions!C42*EXP(-Assumptions!C20*Assumptions!C25) -> 1268.8092 | H15: =Assumptions!C13*Assumptions!C40*EXP(-Assumptions!C20*Assumptions!C23)+Assumptions!C14*0.6*EXP(-Assumptions!C20*Assumptions!C24)+Assumptions!C15*0.6*Assumptions!C42*EXP(-Assumptions!C20*Assumptions!C25) -> 1330.2889 | I15: =Assumptions!C13*Assumptions!C40*EXP(-Assumptions!C20*Assumptions!C23)+Assumptions!C14*0.65*EXP(-Assumptions!C20*Assumptions!C24)+Assumptions!C15*0.65*Assumptions!C42*EXP(-Assumptions!C20*Assumptions!C25) -> 1391.7685 | J15: =Assumptions!C13*Assumptions!C40*EXP(-Assumptions!C20*Assumptions!C23)+Assumptions!C14*0.7*EXP(-Assumptions!C20*Assumptions!C24)+Assumptions!C15*0.7*Assumptions!C42*EXP(-Assumptions!C20*Assumptions!C25) -> 1453.2482 | K15: =Assumptions!C13*Assumptions!C40*EXP(-Assumptions!C20*Assumptions!C23)+Assumptions!C14*0.75*EXP(-Assumptions!C20*Assumptions!C24)+Assumptions!C15*0.75*Assumptions!C42*EXP(-Assumptions!C20*Assumptions!C25) -> 1514.7278 | L15: =Assumptions!C13*Assumptions!C40*EXP(-Assumptions!C20*Assumptions!C23)+Assumptions!C14*0.8*EXP(-Assumptions!C20*Assumptions!C24)+Assumptions!C15*0.8*Assumptions!C42*EXP(-Assumptions!C20*Assumptions!C25) -> 1576.2075 | M15: =Assumptions!C13*Assumptions!C40*EXP(-Assumptions!C20*Assumptions!C23)+Assumptions!C14*0.85*EXP(-Assumptions!C20*Assumptions!C24)+Assumptions!C15*0.85*Assumptions!C42*EXP(-Assumptions!C20*Assumptions!C25) -> 1637.6872 | N15: =Assumptions!C13*Assumptions!C40*EXP(-Assumptions!C20*Assumptions!C23)+Assumptions!C14*0.9*EXP(-Assumptions!C20*Assumptions!C24)+Assumptions!C15*0.9*Assumptions!C42*EXP(-Assumptions!C20*Assumptions!C25) -> 1699.1668
B16: 0.75 | C16: =Assumptions!C13*Assumptions!C40*EXP(-Assumptions!C20*Assumptions!C23)+Assumptions!C14*0.35*EXP(-Assumptions!C20*Assumptions!C24)+Assumptions!C15*0.35*Assumptions!C42*EXP(-Assumptions!C20*Assumptions!C25) -> 1022.8905 | D16: =Assumptions!C13*Assumptions!C40*EXP(-Assumptions!C20*Assumptions!C23)+Assumptions!C14*0.4*EXP(-Assumptions!C20*Assumptions!C24)+Assumptions!C15*0.4*Assumptions!C42*EXP(-Assumptions!C20*Assumptions!C25) -> 1084.3702 | E16: =Assumptions!C13*Assumptions!C40*EXP(-Assumptions!C20*Assumptions!C23)+Assumptions!C14*0.45*EXP(-Assumptions!C20*Assumptions!C24)+Assumptions!C15*0.45*Assumptions!C42*EXP(-Assumptions!C20*Assumptions!C25) -> 1145.8499 | F16: =Assumptions!C13*Assumptions!C40*EXP(-Assumptions!C20*Assumptions!C23)+Assumptions!C14*0.5*EXP(-Assumptions!C20*Assumptions!C24)+Assumptions!C15*0.5*Assumptions!C42*EXP(-Assumptions!C20*Assumptions!C25) -> 1207.3295 | G16: =Assumptions!C13*Assumptions!C40*EXP(-Assumptions!C20*Assumptions!C23)+Assumptions!C14*0.55*EXP(-Assumptions!C20*Assumptions!C24)+Assumptions!C15*0.55*Assumptions!C42*EXP(-Assumptions!C20*Assumptions!C25) -> 1268.8092 | H16: =Assumptions!C13*Assumptions!C40*EXP(-Assumptions!C20*Assumptions!C23)+Assumptions!C14*0.6*EXP(-Assumptions!C20*Assumptions!C24)+Assumptions!C15*0.6*Assumptions!C42*EXP(-Assumptions!C20*Assumptions!C25) -> 1330.2889 | I16: =Assumptions!C13*Assumptions!C40*EXP(-Assumptions!C20*Assumptions!C23)+Assumptions!C14*0.65*EXP(-Assumptions!C20*Assumptions!C24)+Assumptions!C15*0.65*Assumptions!C42*EXP(-Assumptions!C20*Assumptions!C25) -> 1391.7685 | J16: =Assumptions!C13*Assumptions!C40*EXP(-Assumptions!C20*Assumptions!C23)+Assumptions!C14*0.7*EXP(-Assumptions!C20*Assumptions!C24)+Assumptions!C15*0.7*Assumptions!C42*EXP(-Assumptions!C20*Assumptions!C25) -> 1453.2482 | K16: =Assumptions!C13*Assumptions!C40*EXP(-Assumptions!C20*Assumptions!C23)+Assumptions!C14*0.75*EXP(-Assumptions!C20*Assumptions!C24)+Assumptions!C15*0.75*Assumptions!C42*EXP(-Assumptions!C20*Assumptions!C25) -> 1514.7278 | L16: =Assumptions!C13*Assumptions!C40*EXP(-Assumptions!C20*Assumptions!C23)+Assumptions!C14*0.8*EXP(-Assumptions!C20*Assumptions!C24)+Assumptions!C15*0.8*Assumptions!C42*EXP(-Assumptions!C20*Assumptions!C25) -> 1576.2075 | M16: =Assumptions!C13*Assumptions!C40*EXP(-Assumptions!C20*Assumptions!C23)+Assumptions!C14*0.85*EXP(-Assumptions!C20*Assumptions!C24)+Assumptions!C15*0.85*Assumptions!C42*EXP(-Assumptions!C20*Assumptions!C25) -> 1637.6872 | N16: =Assumptions!C13*Assumptions!C40*EXP(-Assumptions!C20*Assumptions!C23)+Assumptions!C14*0.9*EXP(-Assumptions!C20*Assumptions!C24)+Assumptions!C15*0.9*Assumptions!C42*EXP(-Assumptions!C20*Assumptions!C25) -> 1699.1668
B17: 0.8 | C17: =Assumptions!C13*Assumptions!C40*EXP(-Assumptions!C20*Assumptions!C23)+Assumptions!C14*0.35*EXP(-Assumptions!C20*Assumptions!C24)+Assumptions!C15*0.35*Assumptions!C42*EXP(-Assumptions!C20*Assumptions!C25) -> 1022.8905 | D17: =Assumptions!C13*Assumptions!C40*EXP(-Assumptions!C20*Assumptions!C23)+Assumptions!C14*0.4*EXP(-Assumptions!C20*Assumptions!C24)+Assumptions!C15*0.4*Assumptions!C42*EXP(-Assumptions!C20*Assumptions!C25) -> 1084.3702 | E17: =Assumptions!C13*Assumptions!C40*EXP(-Assumptions!C20*Assumptions!C23)+Assumptions!C14*0.45*EXP(-Assumptions!C20*Assumptions!C24)+Assumptions!C15*0.45*Assumptions!C42*EXP(-Assumptions!C20*Assumptions!C25) -> 1145.8499 | F17: =Assumptions!C13*Assumptions!C40*EXP(-Assumptions!C20*Assumptions!C23)+Assumptions!C14*0.5*EXP(-Assumptions!C20*Assumptions!C24)+Assumptions!C15*0.5*Assumptions!C42*EXP(-Assumptions!C20*Assumptions!C25) -> 1207.3295 | G17: =Assumptions!C13*Assumptions!C40*EXP(-Assumptions!C20*Assumptions!C23)+Assumptions!C14*0.55*EXP(-Assumptions!C20*Assumptions!C24)+Assumptions!C15*0.55*Assumptions!C42*EXP(-Assumptions!C20*Assumptions!C25) -> 1268.8092 | H17: =Assumptions!C13*Assumptions!C40*EXP(-Assumptions!C20*Assumptions!C23)+Assumptions!C14*0.6*EXP(-Assumptions!C20*Assumptions!C24)+Assumptions!C15*0.6*Assumptions!C42*EXP(-Assumptions!C20*Assumptions!C25) -> 1330.2889 | I17: =Assumptions!C13*Assumptions!C40*EXP(-Assumptions!C20*Assumptions!C23)+Assumptions!C14*0.65*EXP(-Assumptions!C20*Assumptions!C24)+Assumptions!C15*0.65*Assumptions!C42*EXP(-Assumptions!C20*Assumptions!C25) -> 1391.7685 | J17: =Assumptions!C13*Assumptions!C40*EXP(-Assumptions!C20*Assumptions!C23)+Assumptions!C14*0.7*EXP(-Assumptions!C20*Assumptions!C24)+Assumptions!C15*0.7*Assumptions!C42*EXP(-Assumptions!C20*Assumptions!C25) -> 1453.2482 | K17: =Assumptions!C13*Assumptions!C40*EXP(-Assumptions!C20*Assumptions!C23)+Assumptions!C14*0.75*EXP(-Assumptions!C20*Assumptions!C24)+Assumptions!C15*0.75*Assumptions!C42*EXP(-Assumptions!C20*Assumptions!C25) -> 1514.7278 | L17: =Assumptions!C13*Assumptions!C40*EXP(-Assumptions!C20*Assumptions!C23)+Assumptions!C14*0.8*EXP(-Assumptions!C20*Assumptions!C24)+Assumptions!C15*0.8*Assumptions!C42*EXP(-Assumptions!C20*Assumptions!C25) -> 1576.2075 | M17: =Assumptions!C13*Assumptions!C40*EXP(-Assumptions!C20*Assumptions!C23)+Assumptions!C14*0.85*EXP(-Assumptions!C20*Assumptions!C24)+Assumptions!C15*0.85*Assumptions!C42*EXP(-Assumptions!C20*Assumptions!C25) -> 1637.6872 | N17: =Assumptions!C13*Assumptions!C40*EXP(-Assumptions!C20*Assumptions!C23)+Assumptions!C14*0.9*EXP(-Assumptions!C20*Assumptions!C24)+Assumptions!C15*0.9*Assumptions!C42*EXP(-Assumptions!C20*Assumptions!C25) -> 1699.1668
B21: TABLE 2 — CVR Fair Value: P(M2) vs P(M3|M2) [σ fixed at Assumptions value]
B22: CVR ($mn) | C22: P(M3|M2): Combo Approval Probability (given mono approved)
C23: 0.3 | D23: 0.35 | E23: 0.4 | F23: 0.45 | G23: 0.5 | H23: 0.55 | I23: 0.6 | J23: 0.65 | K23: 0.7 | L23: 0.75 | M23: 0.8 | N23: 0.85
B24: 0.4 | C24: =Assumptions!C13*Assumptions!C40*EXP(-Assumptions!C20*Assumptions!C23)+Assumptions!C14*0.4*EXP(-Assumptions!C20*Assumptions!C24)+Assumptions!C15*0.4*0.3*EXP(-Assumptions!C20*Assumptions!C25) -> 1031.5811 | D24: =Assumptions!C13*Assumptions!C40*EXP(-Assumptions!C20*Assumptions!C23)+Assumptions!C14*0.4*EXP(-Assumptions!C20*Assumptions!C24)+Assumptions!C15*0.4*0.35*EXP(-Assumptions!C20*Assumptions!C25) -> 1042.1389 | E24: =Assumptions!C13*Assumptions!C40*EXP(-Assumptions!C20*Assumptions!C23)+Assumptions!C14*0.4*EXP(-Assumptions!C20*Assumptions!C24)+Assumptions!C15*0.4*0.4*EXP(-Assumptions!C20*Assumptions!C25) -> 1052.6968 | F24: =Assumptions!C13*Assumptions!C40*EXP(-Assumptions!C20*Assumptions!C23)+Assumptions!C14*0.4*EXP(-Assumptions!C20*Assumptions!C24)+Assumptions!C15*0.4*0.45*EXP(-Assumptions!C20*Assumptions!C25) -> 1063.2546 | G24: =Assumptions!C13*Assumptions!C40*EXP(-Assumptions!C20*Assumptions!C23)+Assumptions!C14*0.4*EXP(-Assumptions!C20*Assumptions!C24)+Assumptions!C15*0.4*0.5*EXP(-Assumptions!C20*Assumptions!C25) -> 1073.8124 | H24: =Assumptions!C13*Assumptions!C40*EXP(-Assumptions!C20*Assumptions!C23)+Assumptions!C14*0.4*EXP(-Assumptions!C20*Assumptions!C24)+Assumptions!C15*0.4*0.55*EXP(-Assumptions!C20*Assumptions!C25) -> 1084.3702 | I24: =Assumptions!C13*Assumptions!C40*EXP(-Assumptions!C20*Assumptions!C23)+Assumptions!C14*0.4*EXP(-Assumptions!C20*Assumptions!C24)+Assumptions!C15*0.4*0.6*EXP(-Assumptions!C20*Assumptions!C25) -> 1094.928 | J24: =Assumptions!C13*Assumptions!C40*EXP(-Assumptions!C20*Assumptions!C23)+Assumptions!C14*0.4*EXP(-Assumptions!C20*Assumptions!C24)+Assumptions!C15*0.4*0.65*EXP(-Assumptions!C20*Assumptions!C25) -> 1105.4858 | K24: =Assumptions!C13*Assumptions!C40*EXP(-Assumptions!C20*Assumptions!C23)+Assumptions!C14*0.4*EXP(-Assumptions!C20*Assumptions!C24)+Assumptions!C15*0.4*0.7*EXP(-Assumptions!C20*Assumptions!C25) -> 1116.0436 | L24: =Assumptions!C13*Assumptions!C40*EXP(-Assumptions!C20*Assumptions!C23)+Assumptions!C14*0.4*EXP(-Assumptions!C20*Assumptions!C24)+Assumptions!C15*0.4*0.75*EXP(-Assumptions!C20*Assumptions!C25) -> 1126.6015 | M24: =Assumptions!C13*Assumptions!C40*EXP(-Assumptions!C20*Assumptions!C23)+Assumptions!C14*0.4*EXP(-Assumptions!C20*Assumptions!C24)+Assumptions!C15*0.4*0.8*EXP(-Assumptions!C20*Assumptions!C25) -> 1137.1593 | N24: =Assumptions!C13*Assumptions!C40*EXP(-Assumptions!C20*Assumptions!C23)+Assumptions!C14*0.4*EXP(-Assumptions!C20*Assumptions!C24)+Assumptions!C15*0.4*0.85*EXP(-Assumptions!C20*Assumptions!C25) -> 1147.7171
B25: 0.45 | C25: =Assumptions!C13*Assumptions!C40*EXP(-Assumptions!C20*Assumptions!C23)+Assumptions!C14*0.45*EXP(-Assumptions!C20*Assumptions!C24)+Assumptions!C15*0.45*0.3*EXP(-Assumptions!C20*Assumptions!C25) -> 1086.4622 | D25: =Assumptions!C13*Assumptions!C40*EXP(-Assumptions!C20*Assumptions!C23)+Assumptions!C14*0.45*EXP(-Assumptions!C20*Assumptions!C24)+Assumptions!C15*0.45*0.35*EXP(-Assumptions!C20*Assumptions!C25) -> 1098.3397 | E25: =Assumptions!C13*Assumptions!C40*EXP(-Assumptions!C20*Assumptions!C23)+Assumptions!C14*0.45*EXP(-Assumptions!C20*Assumptions!C24)+Assumptions!C15*0.45*0.4*EXP(-Assumptions!C20*Assumptions!C25) -> 1110.2172 | F25: =Assumptions!C13*Assumptions!C40*EXP(-Assumptions!C20*Assumptions!C23)+Assumptions!C14*0.45*EXP(-Assumptions!C20*Assumptions!C24)+Assumptions!C15*0.45*0.45*EXP(-Assumptions!C20*Assumptions!C25) -> 1122.0948 | G25: =Assumptions!C13*Assumptions!C40*EXP(-Assumptions!C20*Assumptions!C23)+Assumptions!C14*0.45*EXP(-Assumptions!C20*Assumptions!C24)+Assumptions!C15*0.45*0.5*EXP(-Assumptions!C20*Assumptions!C25) -> 1133.9723 | H25: =Assumptions!C13*Assumptions!C40*EXP(-Assumptions!C20*Assumptions!C23)+Assumptions!C14*0.45*EXP(-Assumptions!C20*Assumptions!C24)+Assumptions!C15*0.45*0.55*EXP(-Assumptions!C20*Assumptions!C25) -> 1145.8499 | I25: =Assumptions!C13*Assumptions!C40*EXP(-Assumptions!C20*Assumptions!C23)+Assumptions!C14*0.45*EXP(-Assumptions!C20*Assumptions!C24)+Assumptions!C15*0.45*0.6*EXP(-Assumptions!C20*Assumptions!C25) -> 1157.7274 | J25: =Assumptions!C13*Assumptions!C40*EXP(-Assumptions!C20*Assumptions!C23)+Assumptions!C14*0.45*EXP(-Assumptions!C20*Assumptions!C24)+Assumptions!C15*0.45*0.65*EXP(-Assumptions!C20*Assumptions!C25) -> 1169.6049 | K25: =Assumptions!C13*Assumptions!C40*EXP(-Assumptions!C20*Assumptions!C23)+Assumptions!C14*0.45*EXP(-Assumptions!C20*Assumptions!C24)+Assumptions!C15*0.45*0.7*EXP(-Assumptions!C20*Assumptions!C25) -> 1181.4825 | L25: =Assumptions!C13*Assumptions!C40*EXP(-Assumptions!C20*Assumptions!C23)+Assumptions!C14*0.45*EXP(-Assumptions!C20*Assumptions!C24)+Assumptions!C15*0.45*0.75*EXP(-Assumptions!C20*Assumptions!C25) -> 1193.36 | M25: =Assumptions!C13*Assumptions!C40*EXP(-Assumptions!C20*Assumptions!C23)+Assumptions!C14*0.45*EXP(-Assumptions!C20*Assumptions!C24)+Assumptions!C15*0.45*0.8*EXP(-Assumptions!C20*Assumptions!C25) -> 1205.2376 | N25: =Assumptions!C13*Assumptions!C40*EXP(-Assumptions!C20*Assumptions!C23)+Assumptions!C14*0.45*EXP(-Assumptions!C20*Assumptions!C24)+Assumptions!C15*0.45*0.85*EXP(-Assumptions!C20*Assumptions!C25) -> 1217.1151
